#VRML_SIM R2023b utf8

EXTERNPROTO "https://raw.githubusercontent.com/cyberbotics/webots/R2023a/projects/objects/backgrounds/protos/TexturedBackground.proto"
EXTERNPROTO "https://raw.githubusercontent.com/cyberbotics/webots/R2023a/projects/objects/backgrounds/protos/TexturedBackgroundLight.proto"
EXTERNPROTO "https://raw.githubusercontent.com/cyberbotics/webots/R2023a/projects/objects/floors/protos/RectangleArena.proto"
EXTERNPROTO "https://raw.githubusercontent.com/cyberbotics/webots/R2023a/projects/appearances/protos/Parquetry.proto"
EXTERNPROTO "https://raw.githubusercontent.com/cyberbotics/webots/R2023b/projects/objects/lights/protos/FloorLight.proto"
EXTERNPROTO "https://raw.githubusercontent.com/cyberbotics/webots/R2023a/projects/appearances/protos/BrushedAluminium.proto"

WorldInfo {
}
Viewpoint {
  orientation 0.10819455918632562 0.986119112232492 -0.12594853652297258 1.4332677518659211
  position -13.693968153767601 -0.9559677675562925 72.77195088975145
}
TexturedBackground {
  texture "dusk"
}
TexturedBackgroundLight {
  castShadows FALSE
}
RectangleArena {
  translation 0.45 0.45 0
  floorSize 30 30
  floorTileSize 1 1
  floorAppearance Parquetry {
    type "dark strip"
    colorOverride 0.333333 0.333333 0.498039
  }
  wallHeight 0.02
  wallAppearance BrushedAluminium {
    colorOverride 1 0 0
  }
}
DEF Centrale_server Robot {
  translation -2.6 0 14.16
  children [
    Camera {
      translation 3.21 0 19.95
      rotation 0 1 0 1.5708
      width 1280
      height 720
      far 34
    }
    Solid {
      children [
        Shape {
          appearance Appearance {
            material Material {
            }
            texture ImageTexture {
              url [
                "../controllers/Central_server_py/Required.jpg"
              ]
            }
          }
          geometry Box {
            size 0.1 0.1 0.1
          }
        }
      ]
    }
  ]
  name "centrale_server"
  controller "Camera"
  supervisor TRUE
}
DEF Charriot Robot {
  translation -4.29151 -7.90504 0.0562855
  rotation 0.0032100727702495486 -0.0016817979515224182 -0.9999934334726703 0.9173524897006584
  children [
    DEF qr-code Pose {
      children [
        DEF QR-CODE Transform {
          translation -0.02 -0.19 1.03
          scale 7 7 0.9
          children [
            Shape {
              appearance PBRAppearance {
                baseColorMap ImageTexture {
                  url [
                    "../../markers/marker3.png"
                  ]
                }
                metalness 0
                IBLStrength 0
              }
              geometry Box {
                size 0.15 0.15 0.01
              }
            }
          ]
        }
        Transform {
          translation 0.36 -0.23 0.63
          rotation 0 0 1 -1.5707953071795862
          scale 2 0.5 7.5
          children [
            Shape {
              appearance PBRAppearance {
                baseColor 0 0.1 0.2
                roughness 1
                metalness 0
              }
              geometry Box {
                size 0.1 0.1 0.1
              }
            }
          ]
        }
        Transform {
          translation -0.42 -0.23 0.63
          rotation 0 0 1 -1.5707953071795862
          scale 2 0.5 7.5
          children [
            Shape {
              appearance PBRAppearance {
                baseColor 0 0.1 0.2
                roughness 1
                metalness 0
              }
              geometry Box {
                size 0.1 0.1 0.1
              }
            }
          ]
        }
        Transform {
          translation -0.02 -0.21 1.01
          rotation 0.5773509358560258 -0.577349935856137 0.577349935856137 -2.094395307179586
          scale 12 0.3 12
          children [
            Shape {
              appearance PBRAppearance {
                roughness 1
                metalness 0
              }
              geometry Box {
                size 0.1 0.1 0.1
              }
            }
          ]
        }
      ]
    }
    DEF TopSpin HingeJoint {
      jointParameters HingeJointParameters {
        axis 0 0 1
        anchor -0.019 0.33 0
      }
      device [
        RotationalMotor {
          name "motor3"
        }
      ]
      endPoint Solid {
        translation 0 -0.010000000000000009 0
        children [
          RangeFinder {
            translation -0.02 0.32 0.76
            rotation -3.69431e-07 -3.88407e-07 -1 -1.5708053071795867
            fieldOfView 0.1
            maxRange 14
          }
          LightSensor {
            translation -0.03 0.39 0.89
            rotation 0 0 1 1.5708
            lookupTable [
              0 0 0
              10 1000 0
            ]
          }
          Transform {
            translation -0.04 0.19 0
            scale 0.01 0.01 0.01
            children [
              Shape {
                appearance PBRAppearance {
                  baseColor 0 0.1 0.2
                  roughness 1
                  metalness 0
                }
                geometry Mesh {
                  url [
                    "../../Robot/top.stl"
                  ]
                }
              }
            ]
          }
        ]
        name "solid(2)"
      }
    }
    DEF bomby Pose {
      translation -0.03 -0.48 0.15
      children [
        Shape {
          geometry Capsule {
            height 0.1
            radius 0.05
          }
        }
      ]
    }
    DEF body Transform {
      translation -0.04 0.18 0
      scale 0.01 0.01 0.01
      children [
        Shape {
          appearance PBRAppearance {
            baseColor 0 0.1 0.2
            roughness 1
            metalness 0
          }
          geometry Mesh {
            url [
              "../../Robot/WeirdBODY.stl"
            ]
          }
        }
      ]
    }
    DEF wheel1 HingeJoint {
      jointParameters HingeJointParameters {
        position -323.3596062998561
        anchor 0.41 0.34 0.29
      }
      device [
        RotationalMotor {
          name "motor1"
          maxTorque 300
        }
      ]
      endPoint Solid {
        translation 0.40998574933038956 0.3402053572110573 0.2897779657796005
        rotation 0.704715824487195 -0.07937443584334111 0.7050356768645712 3.300245552049966
        children [
          DEF wheel Shape {
            appearance PBRAppearance {
              baseColor 0 0 0
              roughness 1
              metalness 0
            }
            geometry Cylinder {
              height 0.1
              radius 0.25
            }
          }
        ]
        boundingObject USE wheel
        physics DEF wheel_physics Physics {
        }
      }
    }
    DEF wheel2 HingeJoint {
      jointParameters HingeJointParameters {
        position -329.45712841819653
        anchor -0.47 0.34 0.29
      }
      device [
        RotationalMotor {
          name "motor2"
          maxTorque 300
        }
      ]
      endPoint Solid {
        translation -0.4700171891213426 0.34025386556522946 0.2898418775890864
        rotation -0.6994159162209038 0.14547026893507622 -0.6997540832269793 2.8525823164779203
        children [
          DEF wheel Shape {
            appearance PBRAppearance {
              baseColor 0 0 0
              roughness 1
              metalness 0
            }
            geometry Cylinder {
              height 0.1
              radius 0.25
            }
          }
        ]
        name "solid(1)"
        boundingObject USE wheel
        physics DEF wheel_physics Physics {
        }
      }
    }
  ]
  name "Charriot(1)"
  boundingObject USE bomby
  physics Physics {
    mass 5
  }
  controller "vector_controller"
}
DEF Charriot Robot {
  translation 0.3014110077253479 -10.006012700501971 -0.056306798305784014
  rotation 0.008003402622368538 -0.001796447629322857 -0.9999663585953176 0.3937702225452206
  children [
    DEF qr-code Pose {
      children [
        DEF QR-CODE Transform {
          translation -0.02 -0.19 1.03
          scale 7 7 0.9
          children [
            Shape {
              appearance PBRAppearance {
                baseColorMap ImageTexture {
                  url [
                    "../../markers/marker8.png"
                  ]
                }
                metalness 0
                IBLStrength 0
              }
              geometry Box {
                size 0.15 0.15 0.01
              }
            }
          ]
        }
        Transform {
          translation 0.36 -0.23 0.63
          rotation 0 0 1 -1.5707953071795862
          scale 2 0.5 7.5
          children [
            Shape {
              appearance PBRAppearance {
                baseColor 0 0.1 0.2
                roughness 1
                metalness 0
              }
              geometry Box {
                size 0.1 0.1 0.1
              }
            }
          ]
        }
        Transform {
          translation -0.42 -0.23 0.63
          rotation 0 0 1 -1.5707953071795862
          scale 2 0.5 7.5
          children [
            Shape {
              appearance PBRAppearance {
                baseColor 0 0.1 0.2
                roughness 1
                metalness 0
              }
              geometry Box {
                size 0.1 0.1 0.1
              }
            }
          ]
        }
        Transform {
          translation -0.02 -0.21 1.01
          rotation 0.5773509358560258 -0.577349935856137 0.577349935856137 -2.094395307179586
          scale 12 0.3 12
          children [
            Shape {
              appearance PBRAppearance {
                roughness 1
                metalness 0
              }
              geometry Box {
                size 0.1 0.1 0.1
              }
            }
          ]
        }
      ]
    }
    DEF TopSpin HingeJoint {
      jointParameters HingeJointParameters {
        axis 0 0 1
        anchor -0.019 0.33 0
      }
      device [
        RotationalMotor {
          name "motor3"
        }
      ]
      endPoint Solid {
        translation 0 -0.010000000000000009 0
        children [
          RangeFinder {
            translation -0.02 0.32 0.76
            rotation -3.69431e-07 -3.88407e-07 -1 -1.5708053071795867
            fieldOfView 0.1
            maxRange 14
          }
          LightSensor {
            translation -0.03 0.39 0.89
            rotation 0 0 1 1.5708
            lookupTable [
              0 0 0
              10 1000 0
            ]
          }
          Transform {
            translation -0.04 0.19 0
            scale 0.01 0.01 0.01
            children [
              Shape {
                appearance PBRAppearance {
                  baseColor 0 0.1 0.2
                  roughness 1
                  metalness 0
                }
                geometry Mesh {
                  url [
                    "../../Robot/top.stl"
                  ]
                }
              }
            ]
          }
        ]
        name "solid(2)"
      }
    }
    DEF bomby Pose {
      translation -0.03 -0.48 0.15
      children [
        Shape {
          geometry Capsule {
            height 0.1
            radius 0.05
          }
        }
      ]
    }
    DEF body Transform {
      translation -0.04 0.18 0
      scale 0.01 0.01 0.01
      children [
        Shape {
          appearance PBRAppearance {
            baseColor 0 0.1 0.2
            roughness 1
            metalness 0
          }
          geometry Mesh {
            url [
              "../../Robot/WeirdBODY.stl"
            ]
          }
        }
      ]
    }
    DEF wheel1 HingeJoint {
      jointParameters HingeJointParameters {
        position -323.35960933549734
        anchor 0.41 0.34 0.29
      }
      device [
        RotationalMotor {
          name "motor1"
          maxTorque 300
        }
      ]
      endPoint Solid {
        translation 0.40998574933038956 0.34020535653704 0.28977796515621074
        rotation 0.7047158852223232 -0.07937335897661411 0.7050357373921459 3.3002434127854743
        children [
          DEF wheel Shape {
            appearance PBRAppearance {
              baseColor 0 0 0
              roughness 1
              metalness 0
            }
            geometry Cylinder {
              height 0.1
              radius 0.25
            }
          }
        ]
        boundingObject USE wheel
        physics DEF wheel_physics Physics {
        }
      }
    }
    DEF wheel2 HingeJoint {
      jointParameters HingeJointParameters {
        position -329.4571136344815
        anchor -0.47 0.34 0.29
      }
      device [
        RotationalMotor {
          name "motor2"
          maxTorque 300
        }
      ]
      endPoint Solid {
        translation -0.4700171891213426 0.34025386790283846 0.2898418813421801
        rotation -0.6994153667450761 0.1454755508615659 -0.6997535343693339 2.8525719765163977
        children [
          DEF wheel Shape {
            appearance PBRAppearance {
              baseColor 0 0 0
              roughness 1
              metalness 0
            }
            geometry Cylinder {
              height 0.1
              radius 0.25
            }
          }
        ]
        name "solid(1)"
        boundingObject USE wheel
        physics DEF wheel_physics Physics {
        }
      }
    }
  ]
  name "Charriot(3)"
  boundingObject USE bomby
  physics Physics {
    mass 5
  }
  controller "vector_controller"
}
DEF Charriot Robot {
  translation 5.28624 -12.0365 -0.0561529
  rotation 0.021901406226536514 -0.011474603262212273 0.9996942842115659 0.129881
  children [
    DEF qr-code Pose {
      children [
        DEF QR-CODE Transform {
          translation -0.02 -0.19 1.03
          scale 7 7 0.9
          children [
            Shape {
              appearance PBRAppearance {
                baseColorMap ImageTexture {
                  url [
                    "../../markers/marker13.png"
                  ]
                }
                metalness 0
                IBLStrength 0
              }
              geometry Box {
                size 0.15 0.15 0.01
              }
            }
          ]
        }
        Transform {
          translation 0.36 -0.23 0.63
          rotation 0 0 1 -1.5707953071795862
          scale 2 0.5 7.5
          children [
            Shape {
              appearance PBRAppearance {
                baseColor 0 0.1 0.2
                roughness 1
                metalness 0
              }
              geometry Box {
                size 0.1 0.1 0.1
              }
            }
          ]
        }
        Transform {
          translation -0.42 -0.23 0.63
          rotation 0 0 1 -1.5707953071795862
          scale 2 0.5 7.5
          children [
            Shape {
              appearance PBRAppearance {
                baseColor 0 0.1 0.2
                roughness 1
                metalness 0
              }
              geometry Box {
                size 0.1 0.1 0.1
              }
            }
          ]
        }
        Transform {
          translation -0.02 -0.21 1.01
          rotation 0.5773509358560258 -0.577349935856137 0.577349935856137 -2.094395307179586
          scale 12 0.3 12
          children [
            Shape {
              appearance PBRAppearance {
                roughness 1
                metalness 0
              }
              geometry Box {
                size 0.1 0.1 0.1
              }
            }
          ]
        }
      ]
    }
    DEF TopSpin HingeJoint {
      jointParameters HingeJointParameters {
        axis 0 0 1
        anchor -0.019 0.33 0
      }
      device [
        RotationalMotor {
          name "motor3"
        }
      ]
      endPoint Solid {
        translation 0 -0.010000000000000009 0
        children [
          RangeFinder {
            translation -0.02 0.32 0.76
            rotation -3.69431e-07 -3.88407e-07 -1 -1.5708053071795867
            fieldOfView 0.1
            maxRange 14
          }
          LightSensor {
            translation -0.03 0.39 0.89
            rotation 0 0 1 1.5708
            lookupTable [
              0 0 0
              10 1000 0
            ]
          }
          Transform {
            translation -0.04 0.19 0
            scale 0.01 0.01 0.01
            children [
              Shape {
                appearance PBRAppearance {
                  baseColor 0 0.1 0.2
                  roughness 1
                  metalness 0
                }
                geometry Mesh {
                  url [
                    "../../Robot/top.stl"
                  ]
                }
              }
            ]
          }
        ]
        name "solid(2)"
      }
    }
    DEF bomby Pose {
      translation -0.03 -0.48 0.15
      children [
        Shape {
          geometry Capsule {
            height 0.1
            radius 0.05
          }
        }
      ]
    }
    DEF body Transform {
      translation -0.04 0.18 0
      scale 0.01 0.01 0.01
      children [
        Shape {
          appearance PBRAppearance {
            baseColor 0 0.1 0.2
            roughness 1
            metalness 0
          }
          geometry Mesh {
            url [
              "../../Robot/WeirdBODY.stl"
            ]
          }
        }
      ]
    }
    DEF wheel1 HingeJoint {
      jointParameters HingeJointParameters {
        position -323.3596033451239
        anchor 0.41 0.34 0.29
      }
      device [
        RotationalMotor {
          name "motor1"
          maxTorque 300
        }
      ]
      endPoint Solid {
        translation 0.40998574933038956 0.3402053578671079 0.28977796638637704
        rotation 0.7047157653700418 -0.07937548400841042 0.7050356179494386 3.3002476342964355
        children [
          DEF wheel Shape {
            appearance PBRAppearance {
              baseColor 0 0 0
              roughness 1
              metalness 0
            }
            geometry Cylinder {
              height 0.1
              radius 0.25
            }
          }
        ]
        boundingObject USE wheel
        physics DEF wheel_physics Physics {
        }
      }
    }
    DEF wheel2 HingeJoint {
      jointParameters HingeJointParameters {
        position -329.4571076621207
        anchor -0.47 0.34 0.29
      }
      device [
        RotationalMotor {
          name "motor2"
          maxTorque 300
        }
      ]
      endPoint Solid {
        translation -0.4700171891213426 0.3402538688471756 0.2898418828583736
        rotation -0.6994151447606182 0.14547768466804306 -0.6997533126346092 2.8525677993561143
        children [
          DEF wheel Shape {
            appearance PBRAppearance {
              baseColor 0 0 0
              roughness 1
              metalness 0
            }
            geometry Cylinder {
              height 0.1
              radius 0.25
            }
          }
        ]
        name "solid(1)"
        boundingObject USE wheel
        physics DEF wheel_physics Physics {
        }
      }
    }
  ]
  name "Charriot(4)"
  boundingObject USE bomby
  physics Physics {
    mass 5
  }
  controller "vector_controller"
}
DEF Charriot Robot {
  translation 4.65201 0.262969 -0.0381147
  rotation -0.0007515573014121713 0.001622670650772314 0.9999984010495124 -2.226325307179586
  children [
    DEF qr-code Pose {
      children [
        DEF QR-CODE Transform {
          translation -0.02 -0.19 1.03
          scale 7 7 0.9
          children [
            Shape {
              appearance PBRAppearance {
                baseColorMap ImageTexture {
                  url [
                    "../../markers/marker2.png"
                  ]
                }
                metalness 0
                IBLStrength 0
              }
              geometry Box {
                size 0.15 0.15 0.01
              }
            }
          ]
        }
        Transform {
          translation 0.36 -0.23 0.63
          rotation 0 0 1 -1.5707953071795862
          scale 2 0.5 7.5
          children [
            Shape {
              appearance PBRAppearance {
                baseColor 0 0.1 0.2
                roughness 1
                metalness 0
              }
              geometry Box {
                size 0.1 0.1 0.1
              }
            }
          ]
        }
        Transform {
          translation -0.42 -0.23 0.63
          rotation 0 0 1 -1.5707953071795862
          scale 2 0.5 7.5
          children [
            Shape {
              appearance PBRAppearance {
                baseColor 0 0.1 0.2
                roughness 1
                metalness 0
              }
              geometry Box {
                size 0.1 0.1 0.1
              }
            }
          ]
        }
        Transform {
          translation -0.02 -0.21 1.01
          rotation 0.5773509358560258 -0.577349935856137 0.577349935856137 -2.094395307179586
          scale 12 0.3 12
          children [
            Shape {
              appearance PBRAppearance {
                roughness 1
                metalness 0
              }
              geometry Box {
                size 0.1 0.1 0.1
              }
            }
          ]
        }
      ]
    }
    DEF TopSpin HingeJoint {
      jointParameters HingeJointParameters {
        axis 0 0 1
        anchor -0.019 0.33 0
      }
      device [
        RotationalMotor {
          name "motor3"
        }
      ]
      endPoint Solid {
        translation 0 -0.010000000000000009 0
        children [
          RangeFinder {
            translation -0.02 0.32 0.76
            rotation -3.69431e-07 -3.88407e-07 -1 -1.5708053071795867
            fieldOfView 0.1
            maxRange 14
          }
          LightSensor {
            translation -0.03 0.39 0.89
            rotation 0 0 1 1.5708
            lookupTable [
              0 0 0
              10 1000 0
            ]
          }
          Transform {
            translation -0.04 0.19 0
            scale 0.01 0.01 0.01
            children [
              Shape {
                appearance PBRAppearance {
                  baseColor 0 0.1 0.2
                  roughness 1
                  metalness 0
                }
                geometry Mesh {
                  url [
                    "../../Robot/top.stl"
                  ]
                }
              }
            ]
          }
        ]
        name "solid(2)"
      }
    }
    DEF bomby Pose {
      translation -0.03 -0.48 0.15
      children [
        Shape {
          geometry Capsule {
            height 0.1
            radius 0.05
          }
        }
      ]
    }
    DEF body Transform {
      translation -0.04 0.18 0
      scale 0.01 0.01 0.01
      children [
        Shape {
          appearance PBRAppearance {
            baseColor 0 0.1 0.2
            roughness 1
            metalness 0
          }
          geometry Mesh {
            url [
              "../../Robot/WeirdBODY.stl"
            ]
          }
        }
      ]
    }
    DEF wheel1 HingeJoint {
      jointParameters HingeJointParameters {
        position -323.35961430388716
        anchor 0.41 0.34 0.29
      }
      device [
        RotationalMotor {
          name "motor1"
          maxTorque 300
        }
      ]
      endPoint Solid {
        translation 0.40998574933038956 0.340205355433882 0.289777964135922
        rotation 0.7047159846248221 -0.07937159648470252 0.7050358364549545 3.3002399114819956
        children [
          DEF wheel Shape {
            appearance PBRAppearance {
              baseColor 0 0 0
              roughness 1
              metalness 0
            }
            geometry Cylinder {
              height 0.1
              radius 0.25
            }
          }
        ]
        boundingObject USE wheel
        physics DEF wheel_physics Physics {
        }
      }
    }
    DEF wheel2 HingeJoint {
      jointParameters HingeJointParameters {
        position -329.4571295178098
        anchor -0.47 0.34 0.29
      }
      device [
        RotationalMotor {
          name "motor2"
          maxTorque 300
        }
      ]
      endPoint Solid {
        translation -0.4700171891213426 0.3402538653913556 0.2898418773099328
        rotation -0.6994159570901017 0.145469876065346 -0.6997541240502051 2.852583085564962
        children [
          DEF wheel Shape {
            appearance PBRAppearance {
              baseColor 0 0 0
              roughness 1
              metalness 0
            }
            geometry Cylinder {
              height 0.1
              radius 0.25
            }
          }
        ]
        name "solid(1)"
        boundingObject USE wheel
        physics DEF wheel_physics Physics {
        }
      }
    }
  ]
  name "Charriot(2)"
  boundingObject USE bomby
  physics Physics {
    mass 5
  }
  controller "vector_controller"
}
FloorLight {
  translation 0.31 7.51 0
  scale 0.55
  pointLightIntensity 10
  pointLightRadius 200
}
