#VRML_SIM R2023b utf8

EXTERNPROTO "https://raw.githubusercontent.com/cyberbotics/webots/R2023a/projects/objects/backgrounds/protos/TexturedBackground.proto"
EXTERNPROTO "https://raw.githubusercontent.com/cyberbotics/webots/R2023a/projects/objects/backgrounds/protos/TexturedBackgroundLight.proto"
EXTERNPROTO "https://raw.githubusercontent.com/cyberbotics/webots/R2023a/projects/objects/floors/protos/RectangleArena.proto"
EXTERNPROTO "https://raw.githubusercontent.com/cyberbotics/webots/R2023a/projects/appearances/protos/Parquetry.proto"
EXTERNPROTO "https://raw.githubusercontent.com/cyberbotics/webots/R2023b/projects/objects/lights/protos/FloorLight.proto"
EXTERNPROTO "https://raw.githubusercontent.com/cyberbotics/webots/R2023a/projects/appearances/protos/BrushedAluminium.proto"

WorldInfo {
}
Viewpoint {
  orientation 0.24989862614538425 0.9099172124681821 -0.3310609356369042 1.3850286457548842
  position -10.779342660979475 -0.7579957166512887 43.29418849302777
}
TexturedBackground {
  texture "dusk"
}
TexturedBackgroundLight {
  castShadows FALSE
}
RectangleArena {
  translation 0.45 0.45 0
  floorSize 30 30
  floorTileSize 1 1
  floorAppearance Parquetry {
    type "dark strip"
    colorOverride 0.333333 0.333333 0.498039
  }
  wallHeight 0.02
  wallAppearance BrushedAluminium {
    colorOverride 1 0 0
  }
}
DEF Centrale_server Robot {
  translation -2.6 0 14.16
  children [
    Camera {
      translation 3.21 0 19.95
      rotation 0 1 0 1.5708
      width 1280
      height 720
      far 34
    }
    Solid {
      children [
        Shape {
          appearance Appearance {
            material Material {
            }
            texture ImageTexture {
              url [
                "../controllers/Central_server_py/Required.jpg"
              ]
            }
          }
          geometry Box {
            size 0.1 0.1 0.1
          }
        }
      ]
    }
  ]
  name "centrale_server"
  controller "Camera"
  supervisor TRUE
}
DEF Charriot Robot {
  translation 2.686505272719041 -11.254338801939026 -0.05653132589102232
  rotation 0.004606920685974836 -0.0013332593500547571 -0.999988499284516 0.5808245383406856
  children [
    DEF qr-code Pose {
      children [
        DEF QR-CODE Transform {
          translation -0.02 -0.19 1.03
          rotation 0 0 1 1.5708
          scale 7 7 0.9
          children [
            Shape {
              appearance PBRAppearance {
                baseColorMap ImageTexture {
                  url [
                    "../../markers/marker2.png"
                  ]
                }
                metalness 0
                IBLStrength 0
              }
              geometry Box {
                size 0.15 0.15 0.01
              }
            }
          ]
        }
        Transform {
          translation 0.36 -0.23 0.63
          rotation 0 0 1 -1.5707953071795862
          scale 2 0.5 7.5
          children [
            Shape {
              appearance PBRAppearance {
                baseColor 0 0.1 0.2
                roughness 1
                metalness 0
              }
              geometry Box {
                size 0.1 0.1 0.1
              }
            }
          ]
        }
        Transform {
          translation -0.42 -0.23 0.63
          rotation 0 0 1 -1.5707953071795862
          scale 2 0.5 7.5
          children [
            Shape {
              appearance PBRAppearance {
                baseColor 0 0.1 0.2
                roughness 1
                metalness 0
              }
              geometry Box {
                size 0.1 0.1 0.1
              }
            }
          ]
        }
        Transform {
          translation -0.02 -0.21 1.01
          rotation 0.5773509358560258 -0.577349935856137 0.577349935856137 -2.094395307179586
          scale 12 0.3 12
          children [
            Shape {
              appearance PBRAppearance {
                roughness 1
                metalness 0
              }
              geometry Box {
                size 0.1 0.1 0.1
              }
            }
          ]
        }
      ]
    }
    DEF TopSpin HingeJoint {
      jointParameters HingeJointParameters {
        axis 0 0 1
        anchor -0.019 0.33 0
      }
      device [
        RotationalMotor {
          name "motor3"
        }
      ]
      endPoint Solid {
        translation 0 -0.010000000000000009 0
        children [
          RangeFinder {
            translation -0.02 0.32 0.76
            rotation -3.69431e-07 -3.88407e-07 -1 -1.5708053071795867
            fieldOfView 0.1
            maxRange 14
          }
          LightSensor {
            translation -0.03 0.39 0.89
            rotation 0 0 1 1.5708
            lookupTable [
              0 0 0
              10 1000 0
            ]
          }
          Transform {
            translation -0.04 0.19 0
            scale 0.01 0.01 0.01
            children [
              Shape {
                appearance PBRAppearance {
                  baseColor 0 0.1 0.2
                  roughness 1
                  metalness 0
                }
                geometry Mesh {
                  url [
                    "../../Robot/top.stl"
                  ]
                }
              }
            ]
          }
        ]
        name "solid(2)"
      }
    }
    DEF bomby Pose {
      translation -0.03 -0.48 0.15
      children [
        Shape {
          geometry Capsule {
            height 0.1
            radius 0.05
          }
        }
      ]
    }
    DEF body Transform {
      translation -0.04 0.18 0
      scale 0.01 0.01 0.01
      children [
        Shape {
          appearance PBRAppearance {
            baseColor 0 0.1 0.2
            roughness 1
            metalness 0
          }
          geometry Mesh {
            url [
              "../../Robot/WeirdBODY.stl"
            ]
          }
        }
      ]
    }
    DEF wheel1 HingeJoint {
      jointParameters HingeJointParameters {
        position -31.086202974615045
        anchor 0.41 0.34 0.29
      }
      device [
        RotationalMotor {
          name "motor1"
          maxTorque 300
        }
      ]
      endPoint Solid {
        translation 0.40998574933038956 0.3397724459078174 0.2901992232774868
        rotation -0.16198464558097145 -0.9734309493694351 -0.16184301469549833 4.684998601371217
        children [
          DEF wheel Shape {
            appearance PBRAppearance {
              baseColor 0 0 0
              roughness 1
              metalness 0
            }
            geometry Cylinder {
              height 0.1
              radius 0.25
            }
          }
        ]
        boundingObject USE wheel
        physics DEF wheel_physics Physics {
        }
      }
    }
    DEF wheel2 HingeJoint {
      jointParameters HingeJointParameters {
        position -51.80192188877109
        anchor -0.47 0.34 0.29
      }
      device [
        RotationalMotor {
          name "motor2"
          maxTorque 300
        }
      ]
      endPoint Solid {
        translation -0.4700171891213426 0.34024025056349383 0.2901781294158295
        rotation -0.5704182839472519 0.5906293282107283 -0.5707713885576396 2.074845917582577
        children [
          DEF wheel Shape {
            appearance PBRAppearance {
              baseColor 0 0 0
              roughness 1
              metalness 0
            }
            geometry Cylinder {
              height 0.1
              radius 0.25
            }
          }
        ]
        name "solid(1)"
        boundingObject USE wheel
        physics DEF wheel_physics Physics {
        }
      }
    }
  ]
  name "Charriot(2)"
  boundingObject USE bomby
  physics Physics {
    mass 5
  }
  controller "my_controller123"
}
FloorLight {
  translation 0.31 7.51 0
  scale 0.55
  pointLightIntensity 10
  pointLightRadius 200
}
