#VRML_SIM R2023b utf8

EXTERNPROTO "https://raw.githubusercontent.com/cyberbotics/webots/R2023a/projects/objects/backgrounds/protos/TexturedBackground.proto"
EXTERNPROTO "https://raw.githubusercontent.com/cyberbotics/webots/R2023a/projects/objects/backgrounds/protos/TexturedBackgroundLight.proto"
EXTERNPROTO "https://raw.githubusercontent.com/cyberbotics/webots/R2023a/projects/objects/floors/protos/RectangleArena.proto"
EXTERNPROTO "https://raw.githubusercontent.com/cyberbotics/webots/R2023a/projects/appearances/protos/Parquetry.proto"
EXTERNPROTO "https://raw.githubusercontent.com/cyberbotics/webots/R2023b/projects/objects/lights/protos/FloorLight.proto"
EXTERNPROTO "https://raw.githubusercontent.com/cyberbotics/webots/R2023a/projects/appearances/protos/BrushedAluminium.proto"

WorldInfo {
}
Viewpoint {
  orientation 0.24989862614538425 0.9099172124681821 -0.3310609356369042 1.3850286457548842
  position -10.779342660979475 -0.7579957166512887 43.29418849302777
}
TexturedBackground {
  texture "dusk"
}
TexturedBackgroundLight {
  castShadows FALSE
}
RectangleArena {
  translation 0.45 0.45 0
  floorSize 30 30
  floorTileSize 1 1
  floorAppearance Parquetry {
    type "dark strip"
    colorOverride 0.333333 0.333333 0.498039
  }
  wallHeight 0.02
  wallAppearance BrushedAluminium {
    colorOverride 1 0 0
  }
}
DEF Centrale_server Robot {
  translation -2.6 0 14.16
  children [
    Camera {
      translation 3.21 0 19.95
      rotation 0 1 0 1.5708
      width 1280
      height 720
      far 34
    }
    Solid {
      children [
        Shape {
          appearance Appearance {
            material Material {
            }
            texture ImageTexture {
              url [
                "../controllers/Central_server_py/Required.jpg"
              ]
            }
          }
          geometry Box {
            size 0.1 0.1 0.1
          }
        }
      ]
    }
  ]
  name "centrale_server"
  controller "Camera"
  supervisor TRUE
}
DEF Charriot Robot {
  translation -1.6599768066896354 4.54996913384388 -0.05646079597157884
  rotation 0.000798201941026983 -0.0015036687297619062 -0.9999985509259564 2.0221831156072074
  children [
    DEF qr-code Pose {
      children [
        DEF QR-CODE Transform {
          translation -0.02 -0.19 1.03
          rotation 0 0 1 1.5708
          scale 7 7 0.9
          children [
            Shape {
              appearance PBRAppearance {
                baseColorMap ImageTexture {
                  url [
                    "../../markers/marker1.png"
                  ]
                }
                metalness 0
                IBLStrength 0
              }
              geometry Box {
                size 0.15 0.15 0.01
              }
            }
          ]
        }
        Transform {
          translation 0.36 -0.23 0.63
          rotation 0 0 1 -1.5707953071795862
          scale 2 0.5 7.5
          children [
            Shape {
              appearance PBRAppearance {
                baseColor 0 0.1 0.2
                roughness 1
                metalness 0
              }
              geometry Box {
                size 0.1 0.1 0.1
              }
            }
          ]
        }
        Transform {
          translation -0.42 -0.23 0.63
          rotation 0 0 1 -1.5707953071795862
          scale 2 0.5 7.5
          children [
            Shape {
              appearance PBRAppearance {
                baseColor 0 0.1 0.2
                roughness 1
                metalness 0
              }
              geometry Box {
                size 0.1 0.1 0.1
              }
            }
          ]
        }
        Transform {
          translation -0.02 -0.21 1.01
          rotation 0.5773509358560258 -0.577349935856137 0.577349935856137 -2.094395307179586
          scale 12 0.3 12
          children [
            Shape {
              appearance PBRAppearance {
                roughness 1
                metalness 0
              }
              geometry Box {
                size 0.1 0.1 0.1
              }
            }
          ]
        }
      ]
    }
    DEF TopSpin HingeJoint {
      jointParameters HingeJointParameters {
        axis 0 0 1
        anchor -0.019 0.33 0
      }
      device [
        RotationalMotor {
          name "motor3"
        }
      ]
      endPoint Solid {
        translation 0 -0.010000000000000009 0
        children [
          RangeFinder {
            translation -0.02 0.32 0.76
            rotation -3.69431e-07 -3.88407e-07 -1 -1.5708053071795867
            fieldOfView 0.1
            maxRange 14
          }
          LightSensor {
            translation -0.03 0.39 0.89
            rotation 0 0 1 1.5708
            lookupTable [
              0 0 0
              10 1000 0
            ]
          }
          Transform {
            translation -0.04 0.19 0
            scale 0.01 0.01 0.01
            children [
              Shape {
                appearance PBRAppearance {
                  baseColor 0 0.1 0.2
                  roughness 1
                  metalness 0
                }
                geometry Mesh {
                  url [
                    "../../Robot/top.stl"
                  ]
                }
              }
            ]
          }
        ]
        name "solid(2)"
      }
    }
    DEF bomby Pose {
      translation -0.03 -0.48 0.15
      children [
        Shape {
          geometry Capsule {
            height 0.1
            radius 0.05
          }
        }
      ]
    }
    DEF body Transform {
      translation -0.04 0.18 0
      scale 0.01 0.01 0.01
      children [
        Shape {
          appearance PBRAppearance {
            baseColor 0 0.1 0.2
            roughness 1
            metalness 0
          }
          geometry Mesh {
            url [
              "../../Robot/WeirdBODY.stl"
            ]
          }
        }
      ]
    }
    DEF wheel1 HingeJoint {
      jointParameters HingeJointParameters {
        position -196.90426464530492
        anchor 0.41 0.34 0.29
      }
      device [
        RotationalMotor {
          name "motor1"
          maxTorque 300
        }
      ]
      endPoint Solid {
        translation 0.40998574933038956 0.34030227905371635 0.2899900927881809
        rotation 0.657767837002845 -0.3663422645202341 0.65812978798318 3.8438846487156297
        children [
          DEF wheel Shape {
            appearance PBRAppearance {
              baseColor 0 0 0
              roughness 1
              metalness 0
            }
            geometry Cylinder {
              height 0.1
              radius 0.25
            }
          }
        ]
        boundingObject USE wheel
        physics DEF wheel_physics Physics {
        }
        linearVelocity 4.890188792962729e-07 -2.3648351165202194e-07 -6.853371608472247e-06
        angularVelocity 1.002227690259523e-06 2.073319792697684e-06 -2.2873482593928528e-11
      }
    }
    DEF wheel2 HingeJoint {
      jointParameters HingeJointParameters {
        position -194.42597086488368
        anchor -0.47 0.34 0.29
      }
      device [
        RotationalMotor {
          name "motor2"
          maxTorque 300
        }
      ]
      endPoint Solid {
        translation -0.4700171891213426 0.33975561111238173 0.2901724079280409
        rotation -0.1728346718017956 -0.9696826266201831 -0.172753523420359 4.6811291104984765
        children [
          DEF wheel Shape {
            appearance PBRAppearance {
              baseColor 0 0 0
              roughness 1
              metalness 0
            }
            geometry Cylinder {
              height 0.1
              radius 0.25
            }
          }
        ]
        name "solid(1)"
        boundingObject USE wheel
        physics DEF wheel_physics Physics {
        }
        linearVelocity 4.888843899798035e-07 -2.3627536100238038e-07 -6.8542684940342015e-06
        angularVelocity 1.002233511991987e-06 2.073171004075161e-06 -1.394092943720225e-10
      }
    }
  ]
  name "Charriot(8)"
  boundingObject USE bomby
  physics Physics {
    mass 5
  }
  controller "my_controller123"
  linearVelocity 3.2845893020889516e-07 -1.5872845491612232e-07 -4.948370061451319e-06
  angularVelocity 1.0092918602501334e-06 2.0877276420178902e-06 -1.167935782832555e-10
}
DEF Charriot Robot {
  translation 2.686505272719041 -11.254338801939026 -0.05653132589102232
  rotation 0.004606920685974836 -0.0013332593500547571 -0.999988499284516 0.5808245383406856
  children [
    DEF qr-code Pose {
      children [
        DEF QR-CODE Transform {
          translation -0.02 -0.19 1.03
          rotation 0 0 1 1.5708
          scale 7 7 0.9
          children [
            Shape {
              appearance PBRAppearance {
                baseColorMap ImageTexture {
                  url [
                    "../../markers/marker2.png"
                  ]
                }
                metalness 0
                IBLStrength 0
              }
              geometry Box {
                size 0.15 0.15 0.01
              }
            }
          ]
        }
        Transform {
          translation 0.36 -0.23 0.63
          rotation 0 0 1 -1.5707953071795862
          scale 2 0.5 7.5
          children [
            Shape {
              appearance PBRAppearance {
                baseColor 0 0.1 0.2
                roughness 1
                metalness 0
              }
              geometry Box {
                size 0.1 0.1 0.1
              }
            }
          ]
        }
        Transform {
          translation -0.42 -0.23 0.63
          rotation 0 0 1 -1.5707953071795862
          scale 2 0.5 7.5
          children [
            Shape {
              appearance PBRAppearance {
                baseColor 0 0.1 0.2
                roughness 1
                metalness 0
              }
              geometry Box {
                size 0.1 0.1 0.1
              }
            }
          ]
        }
        Transform {
          translation -0.02 -0.21 1.01
          rotation 0.5773509358560258 -0.577349935856137 0.577349935856137 -2.094395307179586
          scale 12 0.3 12
          children [
            Shape {
              appearance PBRAppearance {
                roughness 1
                metalness 0
              }
              geometry Box {
                size 0.1 0.1 0.1
              }
            }
          ]
        }
      ]
    }
    DEF TopSpin HingeJoint {
      jointParameters HingeJointParameters {
        axis 0 0 1
        anchor -0.019 0.33 0
      }
      device [
        RotationalMotor {
          name "motor3"
        }
      ]
      endPoint Solid {
        translation 0 -0.010000000000000009 0
        children [
          RangeFinder {
            translation -0.02 0.32 0.76
            rotation -3.69431e-07 -3.88407e-07 -1 -1.5708053071795867
            fieldOfView 0.1
            maxRange 14
          }
          LightSensor {
            translation -0.03 0.39 0.89
            rotation 0 0 1 1.5708
            lookupTable [
              0 0 0
              10 1000 0
            ]
          }
          Transform {
            translation -0.04 0.19 0
            scale 0.01 0.01 0.01
            children [
              Shape {
                appearance PBRAppearance {
                  baseColor 0 0.1 0.2
                  roughness 1
                  metalness 0
                }
                geometry Mesh {
                  url [
                    "../../Robot/top.stl"
                  ]
                }
              }
            ]
          }
        ]
        name "solid(2)"
      }
    }
    DEF bomby Pose {
      translation -0.03 -0.48 0.15
      children [
        Shape {
          geometry Capsule {
            height 0.1
            radius 0.05
          }
        }
      ]
    }
    DEF body Transform {
      translation -0.04 0.18 0
      scale 0.01 0.01 0.01
      children [
        Shape {
          appearance PBRAppearance {
            baseColor 0 0.1 0.2
            roughness 1
            metalness 0
          }
          geometry Mesh {
            url [
              "../../Robot/WeirdBODY.stl"
            ]
          }
        }
      ]
    }
    DEF wheel1 HingeJoint {
      jointParameters HingeJointParameters {
        position -31.086202974615045
        anchor 0.41 0.34 0.29
      }
      device [
        RotationalMotor {
          name "motor1"
          maxTorque 300
        }
      ]
      endPoint Solid {
        translation 0.40998574933038956 0.3397724459078174 0.2901992232774868
        rotation -0.16198464558097136 -0.9734309493694353 -0.1618430146954982 4.684998601371218
        children [
          DEF wheel Shape {
            appearance PBRAppearance {
              baseColor 0 0 0
              roughness 1
              metalness 0
            }
            geometry Cylinder {
              height 0.1
              radius 0.25
            }
          }
        ]
        boundingObject USE wheel
        physics DEF wheel_physics Physics {
        }
        linearVelocity 1.491136968382985e-12 6.230318420632032e-13 -4.123514019981039e-16
        angularVelocity -1.8444234481406182e-12 1.2247520156640623e-12 -5.5599505760711346e-12
      }
    }
    DEF wheel2 HingeJoint {
      jointParameters HingeJointParameters {
        position -51.80192188877109
        anchor -0.47 0.34 0.29
      }
      device [
        RotationalMotor {
          name "motor2"
          maxTorque 300
        }
      ]
      endPoint Solid {
        translation -0.4700171891213426 0.34024025056349383 0.2901781294158295
        rotation -0.5704182839472518 0.5906293282107286 -0.5707713885576398 2.0748459175825764
        children [
          DEF wheel Shape {
            appearance PBRAppearance {
              baseColor 0 0 0
              roughness 1
              metalness 0
            }
            geometry Cylinder {
              height 0.1
              radius 0.25
            }
          }
        ]
        name "solid(1)"
        boundingObject USE wheel
        physics DEF wheel_physics Physics {
        }
        linearVelocity 4.180262976504848e-12 4.690789931821108e-12 9.335597980353346e-16
        angularVelocity -2.969343405272307e-11 1.9503516775753496e-11 -5.559972954494047e-12
      }
    }
  ]
  name "Charriot(2)"
  boundingObject USE bomby
  physics Physics {
    mass 5
  }
  controller "my_controller123"
  linearVelocity -9.79311241034766e-13 5.139621417927633e-12 -9.693833838545248e-16
  angularVelocity 1.272553382129638e-14 6.42071830371209e-15 -5.566754153788861e-12
}
DEF Charriot Robot {
  translation 1.7759161448374952 7.141434565881238 -0.05655978788992226
  rotation 0.003350983134679258 0.001324341408254161 0.9999935084948628 0.7631759436031333
  children [
    DEF qr-code Pose {
      children [
        DEF QR-CODE Transform {
          translation -0.02 -0.19 1.03
          rotation 0 0 1 1.5708
          scale 7 7 0.9
          children [
            Shape {
              appearance PBRAppearance {
                baseColorMap ImageTexture {
                  url [
                    "../../markers/marker4.png"
                  ]
                }
                metalness 0
                IBLStrength 0
              }
              geometry Box {
                size 0.15 0.15 0.01
              }
            }
          ]
        }
        Transform {
          translation 0.36 -0.23 0.63
          rotation 0 0 1 -1.5707953071795862
          scale 2 0.5 7.5
          children [
            Shape {
              appearance PBRAppearance {
                baseColor 0 0.1 0.2
                roughness 1
                metalness 0
              }
              geometry Box {
                size 0.1 0.1 0.1
              }
            }
          ]
        }
        Transform {
          translation -0.42 -0.23 0.63
          rotation 0 0 1 -1.5707953071795862
          scale 2 0.5 7.5
          children [
            Shape {
              appearance PBRAppearance {
                baseColor 0 0.1 0.2
                roughness 1
                metalness 0
              }
              geometry Box {
                size 0.1 0.1 0.1
              }
            }
          ]
        }
        Transform {
          translation -0.02 -0.21 1.01
          rotation 0.5773509358560258 -0.577349935856137 0.577349935856137 -2.094395307179586
          scale 12 0.3 12
          children [
            Shape {
              appearance PBRAppearance {
                roughness 1
                metalness 0
              }
              geometry Box {
                size 0.1 0.1 0.1
              }
            }
          ]
        }
      ]
    }
    DEF TopSpin HingeJoint {
      jointParameters HingeJointParameters {
        axis 0 0 1
        anchor -0.019 0.33 0
      }
      device [
        RotationalMotor {
          name "motor3"
        }
      ]
      endPoint Solid {
        translation 0 -0.010000000000000009 0
        children [
          RangeFinder {
            translation -0.02 0.32 0.76
            rotation -3.69431e-07 -3.88407e-07 -1 -1.5708053071795867
            fieldOfView 0.1
            maxRange 14
          }
          LightSensor {
            translation -0.03 0.39 0.89
            rotation 0 0 1 1.5708
            lookupTable [
              0 0 0
              10 1000 0
            ]
          }
          Transform {
            translation -0.04 0.19 0
            scale 0.01 0.01 0.01
            children [
              Shape {
                appearance PBRAppearance {
                  baseColor 0 0.1 0.2
                  roughness 1
                  metalness 0
                }
                geometry Mesh {
                  url [
                    "../../Robot/top.stl"
                  ]
                }
              }
            ]
          }
        ]
        name "solid(2)"
      }
    }
    DEF bomby Pose {
      translation -0.03 -0.48 0.15
      children [
        Shape {
          geometry Capsule {
            height 0.1
            radius 0.05
          }
        }
      ]
    }
    DEF body Transform {
      translation -0.04 0.18 0
      scale 0.01 0.01 0.01
      children [
        Shape {
          appearance PBRAppearance {
            baseColor 0 0.1 0.2
            roughness 1
            metalness 0
          }
          geometry Mesh {
            url [
              "../../Robot/WeirdBODY.stl"
            ]
          }
        }
      ]
    }
    DEF wheel1 HingeJoint {
      jointParameters HingeJointParameters {
        position -7.491931223436996
        anchor 0.41 0.34 0.29
      }
      device [
        RotationalMotor {
          name "motor1"
          maxTorque 300
        }
      ]
      endPoint Solid {
        translation 0.40998574933038956 0.34019176436419796 0.2902338743418706
        rotation 0.4938327152809636 -0.7154687955960688 0.49420001198557423 4.38339301428479
        children [
          DEF wheel Shape {
            appearance PBRAppearance {
              baseColor 0 0 0
              roughness 1
              metalness 0
            }
            geometry Cylinder {
              height 0.1
              radius 0.25
            }
          }
        ]
        boundingObject USE wheel
        physics DEF wheel_physics Physics {
        }
        linearVelocity -3.7553234139220235e-07 3.923728803811563e-07 -6.853650150412159e-06
        angularVelocity -1.6636652072787765e-06 -1.5922616745702663e-06 6.890061456647847e-12
      }
    }
    DEF wheel2 HingeJoint {
      jointParameters HingeJointParameters {
        position -7.491659350135066
        anchor -0.47 0.34 0.29
      }
      device [
        RotationalMotor {
          name "motor2"
          maxTorque 300
        }
      ]
      endPoint Solid {
        translation -0.4700171891213426 0.34017006652568194 0.2902460239803059
        rotation 0.4937661061260468 -0.7155802243054608 0.49410522667147344 4.383486692885376
        children [
          DEF wheel Shape {
            appearance PBRAppearance {
              baseColor 0 0 0
              roughness 1
              metalness 0
            }
            geometry Cylinder {
              height 0.1
              radius 0.25
            }
          }
        ]
        name "solid(1)"
        boundingObject USE wheel
        physics DEF wheel_physics Physics {
        }
        linearVelocity -3.7552310791136744e-07 3.9235127379232955e-07 -6.854185114361033e-06
        angularVelocity -1.6636549940784838e-06 -1.592245775155136e-06 -1.7041415495113747e-13
      }
    }
  ]
  name "Charriot(3)"
  boundingObject USE bomby
  physics Physics {
    mass 5
  }
  controller "my_controller123"
  linearVelocity -2.522080606722114e-07 2.6354692811933103e-07 -4.9480075379991935e-06
  angularVelocity -1.6753156360036836e-06 -1.603392579896371e-06 -4.357761999164343e-12
}
FloorLight {
  translation 0.31 7.51 0
  scale 0.55
  pointLightIntensity 10
  pointLightRadius 200
}
