#VRML_SIM R2023b utf8

EXTERNPROTO "https://raw.githubusercontent.com/cyberbotics/webots/R2023a/projects/objects/backgrounds/protos/TexturedBackground.proto"
EXTERNPROTO "https://raw.githubusercontent.com/cyberbotics/webots/R2023a/projects/objects/backgrounds/protos/TexturedBackgroundLight.proto"
EXTERNPROTO "https://raw.githubusercontent.com/cyberbotics/webots/R2023a/projects/objects/floors/protos/RectangleArena.proto"
EXTERNPROTO "https://raw.githubusercontent.com/cyberbotics/webots/R2023a/projects/appearances/protos/Parquetry.proto"

WorldInfo {
}
Viewpoint {
  orientation 0.08009832703193434 0.10431068966785538 -0.9913140461164169 1.31813333553349
  position 3.1943126252072496 7.403710505821202 2.377486294085727
}
TexturedBackground {
  texture "noon_sunny_garden"
}
TexturedBackgroundLight {
  castShadows FALSE
}
RectangleArena {
  translation 0.45 0.45 0
  rotation 0 1 0 0
  floorSize 50 50
  floorTileSize 1 1
  floorAppearance Parquetry {
    type "dark strip"
    colorOverride 0 0 0
    IBLStrength 0
  }
  wallHeight 0.02
}
DEF Centrale_server Robot {
  translation -1.55 0 0.63
  children [
    Solid {
      children [
        Shape {
          appearance Appearance {
            material Material {
            }
            texture ImageTexture {
              url [
                "../controllers/Central_server_py/Required.jpg"
              ]
            }
          }
          geometry Box {
            size 0.1 0.1 0.1
          }
        }
      ]
    }
  ]
  name "centrale_server"
  controller "Central_server_py"
  supervisor TRUE
}
Robot {
  translation 1.3999959324754456 0.0008835458799053564 -0.0484936106537333
  rotation -0.9999994010571408 0.000991768784758171 -0.00046290391753507187 0.020823705326473832
  children [
    DEF bomby Pose {
      translation -0.03 -0.55 0.06
      children [
        Shape {
          geometry Box {
            size 0.05 0.05 0.05
          }
        }
      ]
    }
    DEF body Transform {
      scale 0.01 0.01 0.01
      children [
        Shape {
          appearance PBRAppearance {
            baseColor 0 0.215686 1
            metalness 0
          }
          geometry Mesh {
            url [
              "../../Robot/body.stl"
            ]
          }
        }
      ]
    }
    HingeJoint {
      jointParameters HingeJointParameters {
        position -0.006746723144401834
        anchor 0.41 0.34 0.29
      }
      device [
        RotationalMotor {
          name "motor1"
        }
      ]
      endPoint Solid {
        translation 0.40998574960683576 0.339847539991399 0.29026357678994025
        rotation 0.0032633995303519864 -0.9999886137340052 0.0034817561442592963 4.711949028069296
        children [
          DEF wheel Shape {
            appearance PBRAppearance {
              metalness 0
            }
            geometry Cylinder {
              height 0.1
              radius 0.25
            }
          }
        ]
        boundingObject USE wheel
        physics DEF wheel_physics Physics {
        }
      }
    }
    HingeJoint {
      jointParameters HingeJointParameters {
        position -0.00678081523847191
        anchor -0.47 0.34 0.29
      }
      device [
        RotationalMotor {
          name "motor2"
        }
      ]
      endPoint Solid {
        translation -0.47001718887655775 0.339828459894665 0.2902478786006252
        rotation 0.0033069522292299893 -0.9999885037826118 0.0034722283287153973 4.711928746553941
        children [
          DEF wheel Shape {
            appearance PBRAppearance {
              metalness 0
            }
            geometry Cylinder {
              height 0.1
              radius 0.25
            }
          }
        ]
        name "solid(1)"
        boundingObject USE wheel
        physics DEF wheel_physics Physics {
        }
      }
    }
  ]
  name "robot(1)"
  boundingObject USE bomby
  physics Physics {
    mass 5
  }
  controller "my_controller123"
}
Robot {
  translation 2.37 0.000874933 0.051489
  rotation -0.9999994010571408 0.000991768784758171 -0.00046290391753507187 0.020823705326473832
  children [
    DEF bomby Pose {
      translation -0.03 -0.55 0.06
      children [
        Shape {
          geometry Box {
            size 0.05 0.05 0.05
          }
        }
      ]
    }
    DEF body Transform {
      scale 0.01 0.01 0.01
      children [
        Shape {
          appearance PBRAppearance {
            baseColor 0 0.215686 1
            metalness 0
          }
          geometry Mesh {
            url [
              "../../Robot/body.stl"
            ]
          }
        }
      ]
    }
    HingeJoint {
      jointParameters HingeJointParameters {
        position -0.006746723144401834
        anchor 0.41 0.34 0.29
      }
      device [
        RotationalMotor {
          name "motor1"
        }
      ]
      endPoint Solid {
        translation 0.40998574960683576 0.339847539991399 0.29026357678994025
        rotation 0.0032633995303519864 -0.9999886137340052 0.0034817561442592963 4.711949028069296
        children [
          DEF wheel Shape {
            appearance PBRAppearance {
              metalness 0
            }
            geometry Cylinder {
              height 0.1
              radius 0.25
            }
          }
        ]
        boundingObject USE wheel
        physics DEF wheel_physics Physics {
        }
      }
    }
    HingeJoint {
      jointParameters HingeJointParameters {
        position -0.00678081523847191
        anchor -0.47 0.34 0.29
      }
      device [
        RotationalMotor {
          name "motor2"
        }
      ]
      endPoint Solid {
        translation -0.47001718887655775 0.339828459894665 0.2902478786006252
        rotation 0.0033069522292299893 -0.9999885037826118 0.0034722283287153973 4.711928746553941
        children [
          DEF wheel Shape {
            appearance PBRAppearance {
              metalness 0
            }
            geometry Cylinder {
              height 0.1
              radius 0.25
            }
          }
        ]
        name "solid(1)"
        boundingObject USE wheel
        physics DEF wheel_physics Physics {
        }
      }
    }
  ]
  name "robot(2)"
  boundingObject USE bomby
  physics Physics {
    mass 5
  }
  controller "my_controller123"
}
Robot {
  translation 3.33 0.000866419 0.151489
  rotation -0.9999994010571408 0.000991768784758171 -0.00046290391753507187 0.020823705326473832
  children [
    DEF bomby Pose {
      translation -0.03 -0.55 0.06
      children [
        Shape {
          geometry Box {
            size 0.05 0.05 0.05
          }
        }
      ]
    }
    DEF body Transform {
      scale 0.01 0.01 0.01
      children [
        Shape {
          appearance PBRAppearance {
            baseColor 0 0.215686 1
            metalness 0
          }
          geometry Mesh {
            url [
              "../../Robot/body.stl"
            ]
          }
        }
      ]
    }
    HingeJoint {
      jointParameters HingeJointParameters {
        position -0.006746723144401834
        anchor 0.41 0.34 0.29
      }
      device [
        RotationalMotor {
          name "motor1"
        }
      ]
      endPoint Solid {
        translation 0.40998574960683576 0.339847539991399 0.29026357678994025
        rotation 0.0032633995303519864 -0.9999886137340052 0.0034817561442592963 4.711949028069296
        children [
          DEF wheel Shape {
            appearance PBRAppearance {
              metalness 0
            }
            geometry Cylinder {
              height 0.1
              radius 0.25
            }
          }
        ]
        boundingObject USE wheel
        physics DEF wheel_physics Physics {
        }
      }
    }
    HingeJoint {
      jointParameters HingeJointParameters {
        position -0.00678081523847191
        anchor -0.47 0.34 0.29
      }
      device [
        RotationalMotor {
          name "motor2"
        }
      ]
      endPoint Solid {
        translation -0.47001718887655775 0.339828459894665 0.2902478786006252
        rotation 0.0033069522292299893 -0.9999885037826118 0.0034722283287153973 4.711928746553941
        children [
          DEF wheel Shape {
            appearance PBRAppearance {
              metalness 0
            }
            geometry Cylinder {
              height 0.1
              radius 0.25
            }
          }
        ]
        name "solid(1)"
        boundingObject USE wheel
        physics DEF wheel_physics Physics {
        }
      }
    }
  ]
  name "robot(3)"
  boundingObject USE bomby
  physics Physics {
    mass 5
  }
  controller "my_controller123"
}
Robot {
  translation 4.37 0.000857116 0.251489
  rotation -0.9999994010571408 0.000991768784758171 -0.00046290391753507187 0.020823705326473832
  children [
    DEF bomby Pose {
      translation -0.03 -0.55 0.06
      children [
        Shape {
          geometry Box {
            size 0.05 0.05 0.05
          }
        }
      ]
    }
    DEF body Transform {
      scale 0.01 0.01 0.01
      children [
        Shape {
          appearance PBRAppearance {
            baseColor 0 0.215686 1
            metalness 0
          }
          geometry Mesh {
            url [
              "../../Robot/body.stl"
            ]
          }
        }
      ]
    }
    HingeJoint {
      jointParameters HingeJointParameters {
        position -0.006746723144401834
        anchor 0.41 0.34 0.29
      }
      device [
        RotationalMotor {
          name "motor1"
        }
      ]
      endPoint Solid {
        translation 0.40998574960683576 0.339847539991399 0.29026357678994025
        rotation 0.0032633995303519864 -0.9999886137340052 0.0034817561442592963 4.711949028069296
        children [
          DEF wheel Shape {
            appearance PBRAppearance {
              metalness 0
            }
            geometry Cylinder {
              height 0.1
              radius 0.25
            }
          }
        ]
        boundingObject USE wheel
        physics DEF wheel_physics Physics {
        }
      }
    }
    HingeJoint {
      jointParameters HingeJointParameters {
        position -0.00678081523847191
        anchor -0.47 0.34 0.29
      }
      device [
        RotationalMotor {
          name "motor2"
        }
      ]
      endPoint Solid {
        translation -0.47001718887655775 0.339828459894665 0.2902478786006252
        rotation 0.0033069522292299893 -0.9999885037826118 0.0034722283287153973 4.711928746553941
        children [
          DEF wheel Shape {
            appearance PBRAppearance {
              metalness 0
            }
            geometry Cylinder {
              height 0.1
              radius 0.25
            }
          }
        ]
        name "solid(1)"
        boundingObject USE wheel
        physics DEF wheel_physics Physics {
        }
      }
    }
  ]
  name "robot(4)"
  boundingObject USE bomby
  physics Physics {
    mass 5
  }
  controller "my_controller123"
}
Robot {
  translation 5.48 0.000847117 0.351489
  rotation -0.9999994010571408 0.000991768784758171 -0.00046290391753507187 0.020823705326473832
  children [
    DEF bomby Pose {
      translation -0.03 -0.55 0.06
      children [
        Shape {
          geometry Box {
            size 0.05 0.05 0.05
          }
        }
      ]
    }
    DEF body Transform {
      scale 0.01 0.01 0.01
      children [
        Shape {
          appearance PBRAppearance {
            baseColor 0 0.215686 1
            metalness 0
          }
          geometry Mesh {
            url [
              "../../Robot/body.stl"
            ]
          }
        }
      ]
    }
    HingeJoint {
      jointParameters HingeJointParameters {
        position -0.006746723144401834
        anchor 0.41 0.34 0.29
      }
      device [
        RotationalMotor {
          name "motor1"
        }
      ]
      endPoint Solid {
        translation 0.40998574960683576 0.339847539991399 0.29026357678994025
        rotation 0.0032633995303519864 -0.9999886137340052 0.0034817561442592963 4.711949028069296
        children [
          DEF wheel Shape {
            appearance PBRAppearance {
              metalness 0
            }
            geometry Cylinder {
              height 0.1
              radius 0.25
            }
          }
        ]
        boundingObject USE wheel
        physics DEF wheel_physics Physics {
        }
      }
    }
    HingeJoint {
      jointParameters HingeJointParameters {
        position -0.00678081523847191
        anchor -0.47 0.34 0.29
      }
      device [
        RotationalMotor {
          name "motor2"
        }
      ]
      endPoint Solid {
        translation -0.47001718887655775 0.339828459894665 0.2902478786006252
        rotation 0.0033069522292299893 -0.9999885037826118 0.0034722283287153973 4.711928746553941
        children [
          DEF wheel Shape {
            appearance PBRAppearance {
              metalness 0
            }
            geometry Cylinder {
              height 0.1
              radius 0.25
            }
          }
        ]
        name "solid(1)"
        boundingObject USE wheel
        physics DEF wheel_physics Physics {
        }
      }
    }
  ]
  name "robot(5)"
  boundingObject USE bomby
  physics Physics {
    mass 5
  }
  controller "my_controller123"
}
Robot {
  children [
    DistanceSensor {
    }
  ]
  controller "Charriot"
}
