#VRML_SIM R2023b utf8

EXTERNPROTO "https://raw.githubusercontent.com/cyberbotics/webots/R2023a/projects/objects/backgrounds/protos/TexturedBackground.proto"
EXTERNPROTO "https://raw.githubusercontent.com/cyberbotics/webots/R2023a/projects/objects/backgrounds/protos/TexturedBackgroundLight.proto"
EXTERNPROTO "https://raw.githubusercontent.com/cyberbotics/webots/R2023a/projects/objects/floors/protos/RectangleArena.proto"
EXTERNPROTO "https://raw.githubusercontent.com/cyberbotics/webots/R2023a/projects/appearances/protos/Parquetry.proto"
EXTERNPROTO "https://raw.githubusercontent.com/cyberbotics/webots/R2023b/projects/objects/lights/protos/FloorLight.proto"
EXTERNPROTO "https://raw.githubusercontent.com/cyberbotics/webots/R2023a/projects/appearances/protos/BrushedAluminium.proto"

WorldInfo {
}
Viewpoint {
  orientation -0.5484224989751014 0.3362531066461512 0.765615184599102 2.2638212252976833
  position 7.849577881550433 -5.064535747329205 16.073053591640505
}
TexturedBackground {
  texture "dusk"
}
TexturedBackgroundLight {
  castShadows FALSE
}
RectangleArena {
  translation 0.45 0.45 0
  floorSize 30 30
  floorTileSize 1 1
  floorAppearance Parquetry {
    type "dark strip"
    colorOverride 0.333333 0.333333 0.498039
  }
  wallHeight 0.02
  wallAppearance BrushedAluminium {
    colorOverride 1 0 0
  }
}
DEF Centrale_server Robot {
  translation -2.6 0 14.16
  children [
    Camera {
      translation 3.21 0 19.95
      rotation 0 1 0 1.5708
      width 1280
      height 720
      far 35
      exposure 2
    }
    Solid {
      children [
        Shape {
          appearance Appearance {
            material Material {
            }
            texture ImageTexture {
              url [
                "../controllers/Central_server_py/Required.jpg"
              ]
            }
          }
          geometry Box {
            size 0.1 0.1 0.1
          }
        }
      ]
    }
  ]
  name "centrale_server"
  controller "Camera"
  supervisor TRUE
}
DEF Charriot Robot {
  translation 5.98027 1.1301 -0.0527014
  rotation 0.0017990960244537993 0.001314567676121485 0.9999975175795787 1.5664473588239554
  children [
    DEF qr-code Pose {
      children [
        DEF QR-CODE Transform {
          translation -0.02 -0.19 1.03
          rotation 0 0 1 1.5708
          scale 7 8 0.9
          children [
            Shape {
              appearance PBRAppearance {
                baseColorMap ImageTexture {
                  url [
                    "../../markers/marker19.png"
                  ]
                }
                metalness 0
                IBLStrength 0
              }
              geometry Box {
                size 0.15 0.15 0.01
              }
            }
          ]
        }
        Transform {
          translation 0.36 -0.23 0.63
          rotation 0 0 1 -1.5707953071795862
          scale 2 0.5 7.5
          children [
            Shape {
              appearance PBRAppearance {
                baseColor 0 0.1 0.2
                roughness 1
                metalness 0
              }
              geometry Box {
                size 0.1 0.1 0.1
              }
            }
          ]
        }
        Transform {
          translation -0.42 -0.23 0.63
          rotation 0 0 1 -1.5707953071795862
          scale 2 0.5 7.5
          children [
            Shape {
              appearance PBRAppearance {
                baseColor 0 0.1 0.2
                roughness 1
                metalness 0
              }
              geometry Box {
                size 0.1 0.1 0.1
              }
            }
          ]
        }
        Transform {
          translation -0.02 -0.21 1.01
          rotation 0.5773509358560258 -0.577349935856137 0.577349935856137 -2.094395307179586
          scale 10 0.3 10
          children [
            Shape {
              appearance PBRAppearance {
                baseColor 0 0.1 0.2
                roughness 1
                metalness 0
              }
              geometry Box {
                size 0.1 0.1 0.1
              }
            }
          ]
        }
      ]
    }
    DEF TopSpin HingeJoint {
      jointParameters HingeJointParameters {
        axis 0 0 1
        anchor -0.019 0.33 0
      }
      device [
        RotationalMotor {
          name "motor3"
        }
      ]
      endPoint Solid {
        translation 0 -0.010000000000000009 0
        children [
          RangeFinder {
            translation -0.02 0.32 0.76
            rotation -3.69431e-07 -3.88407e-07 -1 -1.5708053071795867
            fieldOfView 0.1
            maxRange 14
          }
          LightSensor {
            translation -0.03 0.39 0.89
            rotation 0 0 1 1.5708
            lookupTable [
              0 0 0
              10 1000 0
            ]
          }
          Transform {
            translation -0.04 0.19 0
            scale 0.01 0.01 0.01
            children [
              Shape {
                appearance PBRAppearance {
                  baseColor 0 0.1 0.2
                  roughness 1
                  metalness 0
                }
                geometry Mesh {
                  url [
                    "../../Robot/top.stl"
                  ]
                }
              }
            ]
          }
        ]
        name "solid(2)"
      }
    }
    DEF bomby Pose {
      translation -0.03 -0.48 0.15
      children [
        Shape {
          geometry Capsule {
            height 0.1
            radius 0.05
          }
        }
      ]
    }
    DEF body Transform {
      translation -0.04 0.18 0
      scale 0.01 0.01 0.01
      children [
        Shape {
          appearance PBRAppearance {
            baseColor 0 0.1 0.2
            roughness 1
            metalness 0
          }
          geometry Mesh {
            url [
              "../../Robot/WeirdBODY.stl"
            ]
          }
        }
      ]
    }
    DEF wheel1 HingeJoint {
      jointParameters HingeJointParameters {
        position -4.230473180596777
        anchor 0.41 0.34 0.29
      }
      device [
        RotationalMotor {
          name "motor1"
          maxTorque 300
        }
      ]
      endPoint Solid {
        translation 0.40998574933038956 0.33983757795254155 0.28974487285981093
        rotation -0.6498986700459652 -0.3937152094934162 -0.65009234150699 3.8912093120917626
        children [
          DEF wheel Shape {
            appearance PBRAppearance {
              baseColor 0 0 0
              roughness 1
              metalness 0
            }
            geometry Cylinder {
              height 0.1
              radius 0.25
            }
          }
        ]
        boundingObject USE wheel
        physics DEF wheel_physics Physics {
        }
      }
    }
    DEF wheel2 HingeJoint {
      jointParameters HingeJointParameters {
        position -4.23004785680104
        anchor -0.47 0.34 0.29
      }
      device [
        RotationalMotor {
          name "motor2"
          maxTorque 300
        }
      ]
      endPoint Solid {
        translation -0.4700171891213426 0.3398606135436423 0.2897353836024976
        rotation -0.6499334371874845 -0.39354427762648503 -0.650161079097411 3.8909595844464633
        children [
          DEF wheel Shape {
            appearance PBRAppearance {
              baseColor 0 0 0
              roughness 1
              metalness 0
            }
            geometry Cylinder {
              height 0.1
              radius 0.25
            }
          }
        ]
        name "solid(1)"
        boundingObject USE wheel
        physics DEF wheel_physics Physics {
        }
      }
    }
  ]
  name "Charriot(5)"
  boundingObject USE bomby
  physics Physics {
    mass 5
  }
  controller "my_controller123"
}
DEF Charriot Robot {
  translation 1.2850699998098385 1.22887998677727 -0.05626212616748873
  rotation 0.39781819280375474 -0.00024531891153390257 -0.917464236519869 0.008282460519837784
  children [
    DEF qr-code Pose {
      children [
        DEF QR-CODE Transform {
          translation -0.02 -0.19 1.03
          rotation 0 0 1 1.5708
          scale 7 8 0.9
          children [
            Shape {
              appearance PBRAppearance {
                baseColorMap ImageTexture {
                  url [
                    "../../markers/marker6.png"
                  ]
                }
                metalness 0
                IBLStrength 0
              }
              geometry Box {
                size 0.15 0.15 0.01
              }
            }
          ]
        }
        Transform {
          translation 0.36 -0.23 0.63
          rotation 0 0 1 -1.5707953071795862
          scale 2 0.5 7.5
          children [
            Shape {
              appearance PBRAppearance {
                baseColor 0 0.1 0.2
                roughness 1
                metalness 0
              }
              geometry Box {
                size 0.1 0.1 0.1
              }
            }
          ]
        }
        Transform {
          translation -0.42 -0.23 0.63
          rotation 0 0 1 -1.5707953071795862
          scale 2 0.5 7.5
          children [
            Shape {
              appearance PBRAppearance {
                baseColor 0 0.1 0.2
                roughness 1
                metalness 0
              }
              geometry Box {
                size 0.1 0.1 0.1
              }
            }
          ]
        }
        Transform {
          translation -0.02 -0.21 1.01
          rotation 0.5773509358560258 -0.577349935856137 0.577349935856137 -2.094395307179586
          scale 10 0.3 10
          children [
            Shape {
              appearance PBRAppearance {
                baseColor 0 0.1 0.2
                roughness 1
                metalness 0
              }
              geometry Box {
                size 0.1 0.1 0.1
              }
            }
          ]
        }
      ]
    }
    DEF TopSpin HingeJoint {
      jointParameters HingeJointParameters {
        axis 0 0 1
        anchor -0.019 0.33 0
      }
      device [
        RotationalMotor {
          name "motor3"
        }
      ]
      endPoint Solid {
        translation 0 -0.010000000000000009 0
        children [
          RangeFinder {
            translation -0.02 0.32 0.76
            rotation -3.69431e-07 -3.88407e-07 -1 -1.5708053071795867
            fieldOfView 0.1
            maxRange 14
          }
          LightSensor {
            translation -0.03 0.39 0.89
            rotation 0 0 1 1.5708
            lookupTable [
              0 0 0
              10 1000 0
            ]
          }
          Transform {
            translation -0.04 0.19 0
            scale 0.01 0.01 0.01
            children [
              Shape {
                appearance PBRAppearance {
                  baseColor 0 0.1 0.2
                  roughness 1
                  metalness 0
                }
                geometry Mesh {
                  url [
                    "../../Robot/top.stl"
                  ]
                }
              }
            ]
          }
        ]
        name "solid(2)"
      }
    }
    DEF bomby Pose {
      translation -0.03 -0.48 0.15
      children [
        Shape {
          geometry Capsule {
            height 0.1
            radius 0.05
          }
        }
      ]
    }
    DEF body Transform {
      translation -0.04 0.18 0
      scale 0.01 0.01 0.01
      children [
        Shape {
          appearance PBRAppearance {
            baseColor 0 0.1 0.2
            roughness 1
            metalness 0
          }
          geometry Mesh {
            url [
              "../../Robot/WeirdBODY.stl"
            ]
          }
        }
      ]
    }
    DEF wheel1 HingeJoint {
      jointParameters HingeJointParameters {
        position -4.230430129050358
        anchor 0.41 0.34 0.29
      }
      device [
        RotationalMotor {
          name "motor1"
          maxTorque 300
        }
      ]
      endPoint Solid {
        translation 0.40998574933038956 0.33983758893630994 0.28974486586752685
        rotation -0.649903561507121 -0.39369904894180696 -0.6500972385748738 3.891181332843708
        children [
          DEF wheel Shape {
            appearance PBRAppearance {
              baseColor 0 0 0
              roughness 1
              metalness 0
            }
            geometry Cylinder {
              height 0.1
              radius 0.25
            }
          }
        ]
        boundingObject USE wheel
        physics DEF wheel_physics Physics {
        }
        linearVelocity 6.20599476468279e-09 8.299396049127938e-07 -4.9244350671342216e-05
        angularVelocity -3.331798641655291e-06 2.5811538899991457e-08 1.506147617038693e-10
      }
    }
    DEF wheel2 HingeJoint {
      jointParameters HingeJointParameters {
        position -4.230182717260033
        anchor -0.47 0.34 0.29
      }
      device [
        RotationalMotor {
          name "motor2"
          maxTorque 300
        }
      ]
      endPoint Solid {
        translation -0.4700171891213426 0.33986057785862106 0.2897354024026255
        rotation -0.6499181196820063 -0.3935949010418006 -0.6501457464160635 3.891047233735279
        children [
          DEF wheel Shape {
            appearance PBRAppearance {
              baseColor 0 0 0
              roughness 1
              metalness 0
            }
            geometry Cylinder {
              height 0.1
              radius 0.25
            }
          }
        ]
        name "solid(1)"
        boundingObject USE wheel
        physics DEF wheel_physics Physics {
        }
        linearVelocity 6.099621396586009e-09 8.298052844889376e-07 -4.923896037754089e-05
        angularVelocity -3.331756843467184e-06 2.3334013416079825e-08 1.5029584524950584e-10
      }
    }
  ]
  name "Charriot(1)"
  boundingObject USE bomby
  physics Physics {
    mass 5
  }
  controller "my_controller123"
  linearVelocity 2.57584722977557e-09 3.5090522247093056e-07 -4.649925234839427e-05
  angularVelocity -3.3329997434829643e-06 2.573917256548814e-08 1.500207043421335e-10
}
FloorLight {
  translation 0.31 7.51 0
  scale 0.55
  pointLightIntensity 10
  pointLightRadius 200
}
