#VRML_SIM R2023b utf8

EXTERNPROTO "https://raw.githubusercontent.com/cyberbotics/webots/R2023a/projects/objects/backgrounds/protos/TexturedBackground.proto"
EXTERNPROTO "https://raw.githubusercontent.com/cyberbotics/webots/R2023a/projects/objects/backgrounds/protos/TexturedBackgroundLight.proto"
EXTERNPROTO "https://raw.githubusercontent.com/cyberbotics/webots/R2023a/projects/objects/floors/protos/RectangleArena.proto"
EXTERNPROTO "https://raw.githubusercontent.com/cyberbotics/webots/R2023a/projects/appearances/protos/Parquetry.proto"

WorldInfo {
  physicsDisableTime 0
}
Viewpoint {
  orientation 0.3381948690531396 -0.05898727849730309 -0.9392256020369181 3.4663438507857873
  position 12.3943298195914 -4.193954524129654 10.925380247540543
}
TexturedBackground {
}
TexturedBackgroundLight {
  castShadows FALSE
}
RectangleArena {
  translation 0.45 0.45 0
  rotation 0 1 0 0
  floorSize 50 50
  floorTileSize 1 1
  floorAppearance Parquetry {
    type "dark strip"
    colorOverride 0 0 0
    IBLStrength 0
  }
  wallHeight 0.02
}
DEF Centrale_server Robot {
  translation -1.55 0 0.63
  children [
    Solid {
      children [
        Shape {
          appearance Appearance {
            material Material {
            }
            texture ImageTexture {
              url [
                "../controllers/Central_server_py/Required.jpg"
              ]
            }
          }
          geometry Box {
            size 0.1 0.1 0.1
          }
        }
      ]
    }
  ]
  name "centrale_server"
  controller "Central_server_py"
  supervisor TRUE
}
Robot {
  translation 0.08 0 0
  children [
    DEF bomby Pose {
      translation -0.03 -0.55 0.06
      children [
        Shape {
          geometry Box {
            size 0.05 0.05 0.05
          }
        }
      ]
    }
    DEF body Transform {
      scale 0.01 0.01 0.01
      children [
        Shape {
          appearance PBRAppearance {
          }
          geometry Mesh {
            url [
              "../../Robot/body.stl"
            ]
          }
        }
      ]
    }
    HingeJoint {
      jointParameters HingeJointParameters {
        anchor 0.41 0.34 0.29
      }
      device [
        RotationalMotor {
          name "motor1"
        }
      ]
      endPoint Solid {
        translation 0.40998574960683576 0.3398457651951057 0.2902625421935176
        rotation -0.00010849099999401 -0.9999999882373873 0.00010842014614041862 4.7119596707568405
        children [
          DEF wheel Shape {
            appearance PBRAppearance {
            }
            geometry Cylinder {
              height 0.1
              radius 0.25
            }
          }
        ]
        boundingObject USE wheel
        physics DEF wheel_physics Physics {
        }
      }
    }
    HingeJoint {
      jointParameters HingeJointParameters {
        anchor -0.47 0.34 0.29
      }
      device [
        RotationalMotor {
          name "motor2"
        }
      ]
      endPoint Solid {
        translation -0.47001718887655775 0.3398267830321982 0.29024670972913896
        rotation -8.190833035615494e-05 -0.9999999932960737 8.184667252768942e-05 4.711939680809213
        children [
          DEF wheel Shape {
            appearance PBRAppearance {
            }
            geometry Cylinder {
              height 0.1
              radius 0.25
            }
          }
        ]
        name "solid(1)"
        boundingObject USE wheel
        physics DEF wheel_physics Physics {
        }
      }
    }
  ]
  boundingObject USE bomby
  physics Physics {
    mass 5
  }
  controller "my_controller123"
}
